#### try catch

```js
try{
  console.log(1)
  return 2
} catch (error) {
	return 1
} finally {
  console.log(2)
  return 0
}
// 0
有finally时，return 会走finally，try和catch里的return会忽略
```



#### error类型

```js
RangeError.  数组超出范围时触发。   new Array(-20)

ReferenceError 找不到对象

SyntaxError. 把语法错误的js字符串传入eval函数中

TypeError.  在变量中保存着意外的类型时，或者在访问不存在的方法时
```

可以使用instanceof来判断是哪种错误 `err instanceof RangeError`



#### 抛出错误

```js
throw抛出自定义错误
在遇到throw操作符时，代码会立即停止运行。仅当有try-catch语句捕获到被抛出的值时，代码才会继续执行

throw 123
throw 'abc'
throw new Error('abc')
throw new RangeError('abc')
throw new ReferenceError('abc')
throw new TypeError('abc')

```



#### error事件

```js
window.onerror = function(message , url, line) {
  // 错误消息， 错误所在的url， 行号
  return false // 如果有return false则不会像往常一样显示出错误消息，阻止浏览器报告错误的默认行为
}
try-catch 捕获了错误，就不会触发error事件，所以error是错误捕获的最后一道屏障
```

